<?xml version="1.0" encoding="UTF-8"?>
<testng-results skipped="0" failed="1" ignored="0" total="2" passed="1">
  <reporter-output>
  </reporter-output>
  <suite name="Default suite" duration-ms="3850" started-at="2018-09-23T06:13:17Z" finished-at="2018-09-23T06:13:21Z">
    <groups>
    </groups>
    <test name="Default test" duration-ms="3850" started-at="2018-09-23T06:13:17Z" finished-at="2018-09-23T06:13:21Z">
      <class name="testpackage.RestAssureTest">
        <test-method status="PASS" signature="restAssuredGet()[pri:0, instance:testpackage.RestAssureTest@28feb3fa]" name="restAssuredGet" duration-ms="2536" started-at="2018-09-23T06:13:17Z" finished-at="2018-09-23T06:13:20Z">
          <reporter-output>
          </reporter-output>
        </test-method> <!-- restAssuredGet -->
        <test-method status="FAIL" signature="restAssuredTestPost()[pri:0, instance:testpackage.RestAssureTest@28feb3fa]" name="restAssuredTestPost" duration-ms="1284" started-at="2018-09-23T06:13:20Z" finished-at="2018-09-23T06:13:21Z">
          <exception class="java.lang.AssertionError">
            <message>
              <![CDATA[OPERATION SUCCESS expected [null] but found [Correct Success code was returned]]]>
            </message>
            <full-stacktrace>
              <![CDATA[java.lang.AssertionError: OPERATION SUCCESS expected [null] but found [Correct Success code was returned]
at org.testng.Assert.fail(Assert.java:96)
at org.testng.Assert.failNotEquals(Assert.java:776)
at org.testng.Assert.assertEqualsImpl(Assert.java:132)
at org.testng.Assert.assertEquals(Assert.java:118)
at org.testng.Assert.assertEquals(Assert.java:453)
at testpackage.RestAssureTest.restAssuredTestPost(RestAssureTest.java:44)
at sun.reflect.NativeMethodAccessorImpl.invoke0(Native Method)
at sun.reflect.NativeMethodAccessorImpl.invoke(Unknown Source)
at sun.reflect.DelegatingMethodAccessorImpl.invoke(Unknown Source)
at java.lang.reflect.Method.invoke(Unknown Source)
at org.testng.internal.MethodInvocationHelper.invokeMethod(MethodInvocationHelper.java:124)
at org.testng.internal.Invoker.invokeMethod(Invoker.java:580)
at org.testng.internal.Invoker.invokeTestMethod(Invoker.java:716)
at org.testng.internal.Invoker.invokeTestMethods(Invoker.java:988)
at org.testng.internal.TestMethodWorker.invokeTestMethods(TestMethodWorker.java:125)
at org.testng.internal.TestMethodWorker.run(TestMethodWorker.java:109)
at org.testng.TestRunner.privateRun(TestRunner.java:648)
at org.testng.TestRunner.run(TestRunner.java:505)
at org.testng.SuiteRunner.runTest(SuiteRunner.java:455)
at org.testng.SuiteRunner.runSequentially(SuiteRunner.java:450)
at org.testng.SuiteRunner.privateRun(SuiteRunner.java:415)
at org.testng.SuiteRunner.run(SuiteRunner.java:364)
at org.testng.SuiteRunnerWorker.runSuite(SuiteRunnerWorker.java:52)
at org.testng.SuiteRunnerWorker.run(SuiteRunnerWorker.java:84)
at org.testng.TestNG.runSuitesSequentially(TestNG.java:1208)
at org.testng.TestNG.runSuitesLocally(TestNG.java:1137)
at org.testng.TestNG.runSuites(TestNG.java:1049)
at org.testng.TestNG.run(TestNG.java:1017)
at org.testng.remote.AbstractRemoteTestNG.run(AbstractRemoteTestNG.java:114)
at org.testng.remote.RemoteTestNG.initAndRun(RemoteTestNG.java:251)
at org.testng.remote.RemoteTestNG.main(RemoteTestNG.java:77)
]]>
            </full-stacktrace>
          </exception> <!-- java.lang.AssertionError -->
          <reporter-output>
          </reporter-output>
        </test-method> <!-- restAssuredTestPost -->
      </class> <!-- testpackage.RestAssureTest -->
    </test> <!-- Default test -->
  </suite> <!-- Default suite -->
</testng-results>
